[2025-10-27T08:08:49.550+0000] {local_task_job_runner.py:120} INFO - ::group::Pre task execution logs
[2025-10-27T08:08:49.567+0000] {taskinstance.py:2076} INFO - Dependencies all met for dep_context=non-requeueable deps ti=<TaskInstance: daily_crypto_analysis_test.check_data scheduled__2025-10-26T01:00:00+00:00 [queued]>
[2025-10-27T08:08:49.574+0000] {taskinstance.py:2076} INFO - Dependencies all met for dep_context=requeueable deps ti=<TaskInstance: daily_crypto_analysis_test.check_data scheduled__2025-10-26T01:00:00+00:00 [queued]>
[2025-10-27T08:08:49.575+0000] {taskinstance.py:2306} INFO - Starting attempt 1 of 4
[2025-10-27T08:08:49.584+0000] {taskinstance.py:2330} INFO - Executing <Task(PythonOperator): check_data> on 2025-10-26 01:00:00+00:00
[2025-10-27T08:08:49.589+0000] {logging_mixin.py:188} WARNING - /home/***/.local/lib/python3.12/site-packages/***/task/task_runner/standard_task_runner.py:62 DeprecationWarning: This process (pid=172) is multi-threaded, use of fork() may lead to deadlocks in the child.
[2025-10-27T08:08:49.591+0000] {standard_task_runner.py:64} INFO - Started process 198 to run task
[2025-10-27T08:08:49.590+0000] {standard_task_runner.py:90} INFO - Running: ['***', 'tasks', 'run', 'daily_crypto_analysis_test', 'check_data', 'scheduled__2025-10-26T01:00:00+00:00', '--job-id', '63', '--raw', '--subdir', 'DAGS_FOLDER/test.py', '--cfg-path', '/tmp/tmppxwztoav']
[2025-10-27T08:08:49.594+0000] {standard_task_runner.py:91} INFO - Job 63: Subtask check_data
[2025-10-27T08:08:49.606+0000] {logging_mixin.py:188} WARNING - /home/***/.local/lib/python3.12/site-packages/***/settings.py:195 DeprecationWarning: The sql_alchemy_conn option in [core] has been moved to the sql_alchemy_conn option in [database] - the old setting has been used, but please update your config.
[2025-10-27T08:08:49.629+0000] {task_command.py:426} INFO - Running <TaskInstance: daily_crypto_analysis_test.check_data scheduled__2025-10-26T01:00:00+00:00 [running]> on host 560060c0db65
[2025-10-27T08:08:49.690+0000] {taskinstance.py:2648} INFO - Exporting env vars: AIRFLOW_CTX_DAG_OWNER='***' AIRFLOW_CTX_DAG_ID='daily_crypto_analysis_test' AIRFLOW_CTX_TASK_ID='check_data' AIRFLOW_CTX_EXECUTION_DATE='2025-10-26T01:00:00+00:00' AIRFLOW_CTX_TRY_NUMBER='1' AIRFLOW_CTX_DAG_RUN_ID='scheduled__2025-10-26T01:00:00+00:00'
[2025-10-27T08:08:49.691+0000] {taskinstance.py:430} INFO - ::endgroup::
[2025-10-27T08:08:49.700+0000] {test.py:89} ERROR - ❌ Données insuffisantes : 1 < 50 enregistrements
[2025-10-27T08:08:49.708+0000] {taskinstance.py:441} INFO - ::group::Post task execution logs
[2025-10-27T08:08:49.709+0000] {taskinstance.py:2905} ERROR - Task failed with exception
Traceback (most recent call last):
  File "/home/airflow/.local/lib/python3.12/site-packages/airflow/models/taskinstance.py", line 460, in _execute_task
    result = _execute_callable(context=context, **execute_callable_kwargs)
             ^^^^^^^^^^^^^^^^^^^^^^^^^^^^^^^^^^^^^^^^^^^^^^^^^^^^^^^^^^^^^
  File "/home/airflow/.local/lib/python3.12/site-packages/airflow/models/taskinstance.py", line 432, in _execute_callable
    return execute_callable(context=context, **execute_callable_kwargs)
           ^^^^^^^^^^^^^^^^^^^^^^^^^^^^^^^^^^^^^^^^^^^^^^^^^^^^^^^^^^^^
  File "/home/airflow/.local/lib/python3.12/site-packages/airflow/models/baseoperator.py", line 401, in wrapper
    return func(self, *args, **kwargs)
           ^^^^^^^^^^^^^^^^^^^^^^^^^^^
  File "/home/airflow/.local/lib/python3.12/site-packages/airflow/operators/python.py", line 235, in execute
    return_value = self.execute_callable()
                   ^^^^^^^^^^^^^^^^^^^^^^^
  File "/home/airflow/.local/lib/python3.12/site-packages/airflow/operators/python.py", line 252, in execute_callable
    return self.python_callable(*self.op_args, **self.op_kwargs)
           ^^^^^^^^^^^^^^^^^^^^^^^^^^^^^^^^^^^^^^^^^^^^^^^^^^^^^
  File "/opt/airflow/dags/test.py", line 91, in check_data_availability
    raise ValueError(error_msg)
ValueError: Données insuffisantes : 1 < 50 enregistrements
[2025-10-27T08:08:49.716+0000] {taskinstance.py:1206} INFO - Marking task as UP_FOR_RETRY. dag_id=daily_crypto_analysis_test, task_id=check_data, run_id=scheduled__2025-10-26T01:00:00+00:00, execution_date=20251026T010000, start_date=20251027T080849, end_date=20251027T080849
[2025-10-27T08:08:49.721+0000] {standard_task_runner.py:110} ERROR - Failed to execute job 63 for task check_data (Données insuffisantes : 1 < 50 enregistrements; 198)
[2025-10-27T08:08:49.730+0000] {local_task_job_runner.py:243} INFO - Task exited with return code 1
[2025-10-27T08:08:49.740+0000] {taskinstance.py:3503} INFO - 0 downstream tasks scheduled from follow-on schedule check
[2025-10-27T08:08:49.741+0000] {local_task_job_runner.py:222} INFO - ::endgroup::
